<!-- Rabbit PF Model Description                                         -->
<robot name="rabbit_PF">
  <material name="red">
    <color rgba="0 0 0.8 1"/>
  </material>

  <!-- Linkage Definitions -->
  <link name="Torso">
    <inertial>
      <origin xyz="0 0 0.24" rpy="0 0 0"/>
      <mass value="12"/>
      <inertia ixx="0" ixy="0" ixz="0" iyy="1.33" iyz="0" izz="0"/>
    </inertial>
  </link>
  <link name="LeftThigh">
    <inertial>
      <origin xyz="0 0 -0.11" rpy="0 0 0"/>
      <mass value="6.8"/>
      <inertia ixx="0" ixy="0" ixz="0" iyy="0.47" iyz="0" izz="0"/>
    </inertial>
  </link>
  <link name="LeftShin">
    <inertial>
      <origin xyz="0 0 -0.24" rpy="0 0 0"/>
      <mass value="3.2"/>
      <inertia ixx="0" ixy="0" ixz="0" iyy="0.20" iyz="0" izz="0"/>
    </inertial>
  </link>
  <link name="RightThigh">
    <inertial>
      <origin xyz="0 0 -0.11" rpy="0 0 0"/>
      <mass value="6.8"/>
      <inertia ixx="0" ixy="0" ixz="0" iyy="0.47" iyz="0" izz="0"/>
    </inertial>
  </link>
  <link name="RightShin">
    <inertial>
      <origin xyz="0 0 -0.24" rpy="0 0 0"/>
      <mass value="3.2"/>
      <inertia ixx="0" ixy="0" ixz="0" iyy="0.20" iyz="0" izz="0"/>
    </inertial>
  </link>

<!-- |   ~~~~~~~~~~~~~~~~~~~~~~~~ Joints ~~~~~~~~~~~~~~~~~~~~~~~~~~~~ | -->
  
  <joint name="LeftHip" type="revolute">
    <origin xyz="0 0 0" rpy="0 0 0"/>
    <axis xyz="0 1 0"/>
    <parent link="Torso"/>
    <child link="LeftThigh"/>
  </joint>
  <joint name="LeftKnee" type="revolute">
    <origin xyz="0 0 -0.4" rpy="0 0 0"/>
    <axis xyz="0 1 0"/>
    <parent link="LeftThigh"/>
    <child link="LeftShin"/>
  </joint>
  <joint name="RightHip" type="revolute">
    <origin xyz="0 0 0" rpy="0 0 0"/>
    <axis xyz="0 1 0"/>
    <parent link="Torso"/>
    <child link="RightThigh"/>
  </joint>
  <joint name="RightKnee" type="revolute">
    <origin xyz="0 0 -0.4" rpy="0 0 0"/>
    <axis xyz="0 1 0"/>
    <parent link="RightThigh"/>
    <child link="RightShin"/>
  </joint>
  
  
<!-- |   ~~~~~~~~~~~~~~~~~~~~~~~~ Motors ~~~~~~~~~~~~~~~~~~~~~~~~~~~~ | -->
<transmission name="LeftHipTransmission" type="pr2_mechanism_model/SimpleTransmission">
	<joint name="LeftHip"/>
    <actuator>
	<mechanicalReduction>50</mechanicalReduction>
    <motorInertia>0.000332</motorInertia>
    </actuator>
</transmission>

<transmission name="LeftKneeTransmission" type="pr2_mechanism_model/SimpleTransmission">
	<joint name="LeftKnee"/>
    <actuator>
	<mechanicalReduction>50</mechanicalReduction>
    <motorInertia>0.000332</motorInertia>
    </actuator>
</transmission>

<transmission name="RightHipTransmission" type="pr2_mechanism_model/SimpleTransmission">
	<joint name="RightHip"/>
    <actuator>
	<mechanicalReduction>50</mechanicalReduction>
    <motorInertia>0.000332</motorInertia>
    </actuator>
</transmission>

<transmission name="RightKneeTransmission" type="pr2_mechanism_model/SimpleTransmission">
	<joint name="RightKnee"/>
    <actuator>
	<mechanicalReduction>50</mechanicalReduction>
    <motorInertia>0.000332</motorInertia>
    </actuator>
</transmission>



</robot>
